Workbook
Name UPDATE: 'Data Sheet'!$E$1

Sheet Financials>

Sheet Historical FS
B2: ="Historical Financial Statements "&"- "&'Data Sheet'!$B$1 -> Historical Financial Statements - ITC LTD
B3: Years | C3: ='Data Sheet'!B56 -> 42460 | D3: ='Data Sheet'!C56 -> 42825 | E3: ='Data Sheet'!D56 -> 43190 | F3: ='Data Sheet'!E56 -> 43555 | G3: ='Data Sheet'!F56 -> 43921 | H3: ='Data Sheet'!G56 -> 44286 | I3: ='Data Sheet'!H56 -> 44651 | J3: ='Data Sheet'!I56 -> 45016 | ... L3: ='Data Sheet'!K56 -> 45747 | M3: LTM
A5: # | B5: Income Statement
B7: Sales | C7: =IFERROR('Data Sheet'!B17,0) -> 39192.1 | D7: =IFERROR('Data Sheet'!C17,0) -> 42767.6 | E7: =IFERROR('Data Sheet'!D17,0) -> 43448.94 | F7: =IFERROR('Data Sheet'!E17,0) -> 48339.58 | G7: =IFERROR('Data Sheet'!F17,0) -> 49387.7 | H7: =IFERROR('Data Sheet'!G17,0) -> 49257.45 | I7: =IFERROR('Data Sheet'!H17,0) -> 60644.54 | J7: =IFERROR('Data Sheet'!I17,0) -> 70919.03 | ... L7: =IFERROR('Data Sheet'!K17,0) -> 75323.34 | M7: =IFERROR(SUM('Data Sheet'!H42:K42),0) -> 79808.72
B8: Sales Growth | C8: - | D8: =D7/C7-1 -> 0.09123012 | E8: =E7/D7-1 -> 0.015931219 | F8: =F7/E7-1 -> 0.11256063 | G8: =G7/F7-1 -> 0.021682439 | H8: =H7/G7-1 -> -0.0026372963 | I8: =I7/H7-1 -> 0.23117498 | J8: =J7/I7-1 -> 0.16942152 | K8: =K7/J7-1 -> -0.042119724 | ... M8: =M7/L7-1 -> 0.059548342
B10: COGS | C10: =IFERROR(SUM('Data Sheet'!B18,'Data Sheet'!B20:B21)-1*'Data Sheet'!B19,0) -> 15721.97 | D10: =IFERROR(SUM('Data Sheet'!C18,'Data Sheet'!C20:C21)-1*'Data Sheet'!C19,0) -> 18317.39 | E10: =IFERROR(SUM('Data Sheet'!D18,'Data Sheet'!D20:D21)-1*'Data Sheet'!D19,0) -> 18206.6 | F10: =IFERROR(SUM('Data Sheet'!E18,'Data Sheet'!E20:E21)-1*'Data Sheet'!E19,0) -> 20038.07 | G10: =IFERROR(SUM('Data Sheet'!F18,'Data Sheet'!F20:F21)-1*'Data Sheet'!F19,0) -> 20034.61 | H10: =IFERROR(SUM('Data Sheet'!G18,'Data Sheet'!G20:G21)-1*'Data Sheet'!G19,0) -> 22418.18 | I10: =IFERROR(SUM('Data Sheet'!H18,'Data Sheet'!H20:H21)-1*'Data Sheet'!H19,0) -> 29162.51 | J10: =IFERROR(SUM('Data Sheet'!I18,'Data Sheet'!I20:I21)-1*'Data Sheet'!I19,0) -> 32565.91 | ... L10: =IFERROR(SUM('Data Sheet'!K18,'Data Sheet'!K20:K21)-1*'Data Sheet'!K19,0) -> 35299.43 | M10: =IFERROR(SUM('Data Sheet'!H43:K43),0) -> 52895.65
B11: COGS %Sales | C11: =C10/C7 -> 0.40115151 | D11: =D10/D7 -> 0.42830063 | E11: =E10/E7 -> 0.41903439 | F11: =F10/F7 -> 0.41452718 | G11: =G10/G7 -> 0.40565991 | H11: =H10/H7 -> 0.45512263 | I11: =I10/I7 -> 0.4808761 | J11: =J10/J7 -> 0.45919847 | ... M11: =M10/M7 -> 0.66278033
B13: Gross Profit | C13: =C7-C10 -> 23470.13 | D13: =D7-D10 -> 24450.21 | E13: =E7-E10 -> 25242.34 | F13: =F7-F10 -> 28301.51 | G13: =G7-G10 -> 29353.09 | H13: =H7-H10 -> 26839.27 | I13: =I7-I10 -> 31482.03 | J13: =J7-J10 -> 38353.12 | ... M13: =M7-M10 -> 26913.07
B14: Gross Margins | C14: =C13/C7 -> 0.59884849 | D14: =D13/D7 -> 0.57169937 | E14: =E13/E7 -> 0.58096561 | F14: =F13/F7 -> 0.58547282 | G14: =G13/G7 -> 0.59434009 | H14: =H13/H7 -> 0.54487737 | I14: =I13/I7 -> 0.5191239 | J14: =J13/J7 -> 0.54080153 | ... M14: =M13/M7 -> 0.33721967
B16: Selling and Other Expenses | C16: =IFERROR(SUM('Data Sheet'!B22:B24),0) -> 8938.64 | D16: =IFERROR(SUM('Data Sheet'!C22:C24),0) -> 8980.7 | E16: =IFERROR(SUM('Data Sheet'!D22:D24),0) -> 8721.75 | F16: =IFERROR(SUM('Data Sheet'!E22:E24),0) -> 9764.12 | G16: =IFERROR(SUM('Data Sheet'!F22:F24),0) -> 10009.55 | H16: =IFERROR(SUM('Data Sheet'!G22:G24),0) -> 9774.49 | I16: =IFERROR(SUM('Data Sheet'!H22:H24),0) -> 10858.88 | J16: =IFERROR(SUM('Data Sheet'!I22:I24),0) -> 12648.86 | ... M16: =IFERROR(SUM('Data Sheet'!L22:L24),0) -> 0
B17: S&G Expenses %Sales | C17: =C16/C7 -> 0.22807249 | D17: =D16/D7 -> 0.2099884 | E17: =E16/E7 -> 0.20073562 | F17: =F16/F7 -> 0.20199017 | G17: =G16/G7 -> 0.20267293 | H17: =H16/H7 -> 0.19843678 | I17: =I16/I7 -> 0.17905783 | J17: =J16/J7 -> 0.17835636 | ... M17: =M16/M7 -> 0
B19: EBITDA | C19: =C13-C16 -> 14531.49 | D19: =D13-D16 -> 15469.51 | E19: =E13-E16 -> 16520.59 | F19: =F13-F16 -> 18537.39 | G19: =G13-G16 -> 19343.54 | H19: =H13-H16 -> 17064.78 | I19: =I13-I16 -> 20623.15 | J19: =J13-J16 -> 25704.26 | ... M19: =M13-M16 -> 26913.07
B20: EBITDA Margin | C20: =C19/C7 -> 0.370776 | D20: =D19/D7 -> 0.36171097 | E20: =E19/E7 -> 0.38022999 | F20: =F19/F7 -> 0.38348265 | G20: =G19/G7 -> 0.39166716 | H20: =H19/H7 -> 0.34644059 | I20: =I19/I7 -> 0.34006606 | J20: =J19/J7 -> 0.36244517 | ... M20: =M19/M7 -> 0.33721967
B22: Depreciation | C22: =IFERROR('Data Sheet'!B26,0) -> 1077.4 | D22: =IFERROR('Data Sheet'!C26,0) -> 1152.79 | E22: =IFERROR('Data Sheet'!D26,0) -> 1236.28 | F22: =IFERROR('Data Sheet'!E26,0) -> 1396.61 | G22: =IFERROR('Data Sheet'!F26,0) -> 1644.91 | H22: =IFERROR('Data Sheet'!G26,0) -> 1645.59 | I22: =IFERROR('Data Sheet'!H26,0) -> 1732.41 | J22: =IFERROR('Data Sheet'!I26,0) -> 1809.01 | ... L22: =IFERROR('Data Sheet'!K26,0) -> 1646.32 | M22: =IFERROR(SUM('Data Sheet'!H45:K45),0) -> 1699.61
B23: Depreciation %Sales | C23: =C22/C7 -> 0.027490234 | D23: =D22/D7 -> 0.026954751 | E23: =E22/E7 -> 0.028453629 | F23: =F22/F7 -> 0.028891645 | G23: =G22/G7 -> 0.033306066 | H23: =H22/H7 -> 0.033407941 | I23: =I22/I7 -> 0.028566628 | J23: =J22/J7 -> 0.025508104 | ... M23: =M22/M7 -> 0.021296044
B25: EBIT | C25: =C19-C22 -> 13454.09 | D25: =D19-D22 -> 14316.72 | E25: =E19-E22 -> 15284.31 | F25: =F19-F22 -> 17140.78 | G25: =G19-G22 -> 17698.63 | H25: =H19-H22 -> 15419.19 | I25: =I19-I22 -> 18890.74 | J25: =J19-J22 -> 23895.25 | ... M25: =M19-M22 -> 25213.46
B26: EBIT Margins | C26: =C25/C7 -> 0.34328576 | D26: =D25/D7 -> 0.33475622 | E26: =E25/E7 -> 0.35177636 | F26: =F25/F7 -> 0.354591 | G26: =G25/G7 -> 0.35836109 | H26: =H25/H7 -> 0.31303265 | I26: =I25/I7 -> 0.31149944 | J26: =J25/J7 -> 0.33693707 | ... M26: =M25/M7 -> 0.31592362
B28: Interest | C28: =IFERROR('Data Sheet'!B27,0) -> 78.13 | D28: =IFERROR('Data Sheet'!C27,0) -> 49.03 | E28: =IFERROR('Data Sheet'!D27,0) -> 115.01 | F28: =IFERROR('Data Sheet'!E27,0) -> 71.4 | G28: =IFERROR('Data Sheet'!F27,0) -> 81.38 | H28: =IFERROR('Data Sheet'!G27,0) -> 57.97 | I28: =IFERROR('Data Sheet'!H27,0) -> 59.99 | J28: =IFERROR('Data Sheet'!I27,0) -> 77.77 | ... L28: =IFERROR('Data Sheet'!K27,0) -> 45.06 | M28: =IFERROR(SUM('Data Sheet'!H46:K46),0) -> 66.9
B29: Interest %Sales | C29: =C28/C7 -> 0.001993514 | D29: =D28/D7 -> 0.0011464286 | E29: =E28/E7 -> 0.0026470151 | F29: =F28/F7 -> 0.0014770505 | G29: =G28/G7 -> 0.0016477787 | H29: =H28/H7 -> 0.0011768778 | I29: =I28/I7 -> 0.00098920694 | J29: =J28/J7 -> 0.0010966027 | ... M29: =M28/M7 -> 0.00083825427
B31: Earning Before Tax | C31: =C25-C28 -> 13375.96 | D31: =D25-D28 -> 14267.69 | E31: =E25-E28 -> 15169.3 | F31: =F25-F28 -> 17069.38 | G31: =G25-G28 -> 17617.25 | H31: =H25-H28 -> 15361.22 | I31: =I25-I28 -> 18830.75 | J31: =J25-J28 -> 23817.48 | ... M31: =M25-M28 -> 25146.56
B32: EBT Margins | C32: =C31/C7 -> 0.34129225 | D32: =D31/D7 -> 0.33360979 | E32: =E31/E7 -> 0.34912935 | F32: =F31/F7 -> 0.35311395 | G32: =G31/G7 -> 0.35671331 | H32: =H31/H7 -> 0.31185577 | I32: =I31/I7 -> 0.31051023 | J32: =J31/J7 -> 0.33584046 | ... M32: =M31/M7 -> 0.31508537
B34: Tax | C34: =IFERROR('Data Sheet'!B29,0) -> 5358.21 | D34: =IFERROR('Data Sheet'!C29,0) -> 5549.09 | E34: =IFERROR('Data Sheet'!D29,0) -> 5916.43 | F34: =IFERROR('Data Sheet'!E29,0) -> 6313.92 | G34: =IFERROR('Data Sheet'!F29,0) -> 4441.79 | H34: =IFERROR('Data Sheet'!G29,0) -> 4555.29 | I34: =IFERROR('Data Sheet'!H29,0) -> 5237.34 | J34: =IFERROR('Data Sheet'!I29,0) -> 6438.4 | ... L34: =IFERROR('Data Sheet'!K29,0) -> 6890.47 | M34: =IFERROR(SUM('Data Sheet'!H48:K48),0) -> 6993.21
B35: Effective Tax Rate | C35: =C34/C31 -> 0.40058508 | D35: =D34/D31 -> 0.38892701 | E35: =E34/E31 -> 0.39002657 | F35: =F34/F31 -> 0.36989744 | G35: =G34/G31 -> 0.25212732 | H35: =H34/H31 -> 0.29654481 | I35: =I34/I31 -> 0.278127 | J35: =J34/J31 -> 0.27032247 | ... M35: =M34/M31 -> 0.27809808
B37: Net Profit | C37: =C31-C34 -> 8017.75 | D37: =D31-D34 -> 8718.6 | E37: =E31-E34 -> 9252.87 | F37: =F31-F34 -> 10755.46 | G37: =G31-G34 -> 13175.46 | H37: =H31-H34 -> 10805.93 | I37: =I31-I34 -> 13593.41 | J37: =J31-J34 -> 17379.08 | ... M37: =M31-M34 -> 18153.35
B38: Net Margins | C38: =C37/C7 -> 0.20457567 | D38: =D37/D7 -> 0.20385993 | E38: =E37/E7 -> 0.21295963 | F38: =F37/F7 -> 0.222498 | G38: =G37/G7 -> 0.26677614 | H38: =H37/H7 -> 0.21937656 | I38: =I37/I7 -> 0.22414895 | J38: =J37/J7 -> 0.24505524 | ... M38: =M37/M7 -> 0.22746073
B40: No of Equity Share | C40: =IFERROR('Data Sheet'!$B$6,0) -> 1252.9468 | D40: =IFERROR('Data Sheet'!$B$6,0) -> 1252.9468 | E40: =IFERROR('Data Sheet'!$B$6,0) -> 1252.9468 | F40: =IFERROR('Data Sheet'!$B$6,0) -> 1252.9468 | G40: =IFERROR('Data Sheet'!$B$6,0) -> 1252.9468 | H40: =IFERROR('Data Sheet'!$B$6,0) -> 1252.9468 | I40: =IFERROR('Data Sheet'!$B$6,0) -> 1252.9468 | J40: =IFERROR('Data Sheet'!$B$6,0) -> 1252.9468 | ... M40: =IFERROR('Data Sheet'!$B$6,0) -> 1252.9468
B42: Earnings Per Share | C42: =C37/C40 -> 6.3991147 | D42: =D37/D40 -> 6.958476 | E42: =E37/E40 -> 7.3848868 | F42: =F37/F40 -> 8.5841317 | G42: =G37/G40 -> 10.515579 | H42: =H37/H40 -> 8.6244128 | I42: =I37/I40 -> 10.849152 | J42: =J37/J40 -> 13.870565 | ... M42: =M37/M40 -> 14.488525
B43: EPS Growth | D43: =D42/C42-1 -> 0.087412304 | E43: =E42/D42-1 -> 0.061279334 | F43: =F42/E42-1 -> 0.16239178 | G43: =G42/F42-1 -> 0.225002 | H43: =H42/G42-1 -> -0.1798442 | I43: =I42/H42-1 -> 0.25795836 | J43: =J42/I42-1 -> 0.27849303 | K43: =K42/J42-1 -> 0.0024069168 | ... M43: =M42/L42-1 -> 0.051904668
B45: Dividend Per Share | C45: =IFERROR('Data Sheet'!B31/'Historical FS'!C40,0) -> 5.4592264 | D45: =IFERROR('Data Sheet'!C31/'Historical FS'!D40,0) -> 4.6051598 | E45: =IFERROR('Data Sheet'!D31/'Historical FS'!E40,0) -> 5.0163424 | F45: =IFERROR('Data Sheet'!E31/'Historical FS'!F40,0) -> 5.6256979 | G45: =IFERROR('Data Sheet'!F31/'Historical FS'!G40,0) -> 9.9577894 | H45: =IFERROR('Data Sheet'!G31/'Historical FS'!H40,0) -> 10.560672 | I45: =IFERROR('Data Sheet'!H31/'Historical FS'!I40,0) -> 11.310776 | J45: =IFERROR('Data Sheet'!I31/'Historical FS'!J40,0) -> 15.374476 | ... M45: =IFERROR('Data Sheet'!L31/'Historical FS'!M40,0) -> 0
B46: Dividend Payout Ratio | C46: =C45/C42 -> 0.85312214 | D46: =D45/D42 -> 0.66180579 | E46: =E45/E42 -> 0.6792714 | F46: =F45/F42 -> 0.65536016 | G46: =G45/G42 -> 0.94695593 | H46: =H45/H42 -> 1.2245091 | I46: =I45/I42 -> 1.0425493 | J46: =J45/J42 -> 1.1084246 | ... M46: =M45/M42 -> 0
B48: Retained Earnings | C48: =IFERROR(IF(C42>C45,1-C46,0),0) -> 0.14687786 | D48: =IFERROR(IF(D42>D45,1-D46,0),0) -> 0.33819421 | E48: =IFERROR(IF(E42>E45,1-E46,0),0) -> 0.3207286 | F48: =IFERROR(IF(F42>F45,1-F46,0),0) -> 0.34463984 | G48: =IFERROR(IF(G42>G45,1-G46,0),0) -> 0.053044068 | H48: =IFERROR(IF(H42>H45,1-H46,0),0) -> 0 | I48: =IFERROR(IF(I42>I45,1-I46,0),0) -> 0 | J48: =IFERROR(IF(J42>J45,1-J46,0),0) -> 0 | ... M48: =IFERROR(IF(M42>M45,1-M46,0),0) -> 1
A50: # | B50: Balance Sheet
B52: Equity Share Capital | C52: =IFERROR('Data Sheet'!B57,0) -> 804.72 | D52: =IFERROR('Data Sheet'!C57,0) -> 1214.74 | E52: =IFERROR('Data Sheet'!D57,0) -> 1220.43 | F52: =IFERROR('Data Sheet'!E57,0) -> 1225.86 | G52: =IFERROR('Data Sheet'!F57,0) -> 1229.22 | H52: =IFERROR('Data Sheet'!G57,0) -> 1230.88 | I52: =IFERROR('Data Sheet'!H57,0) -> 1232.33 | J52: =IFERROR('Data Sheet'!I57,0) -> 1242.8 | ... L52: =IFERROR('Data Sheet'!K57,0) -> 1251.41 | M52: 0
B53: Reserves | C53: =IFERROR('Data Sheet'!B58,0) -> 41874.8 | D53: =IFERROR('Data Sheet'!C58,0) -> 45198.19 | E53: =IFERROR('Data Sheet'!D58,0) -> 51289.68 | F53: =IFERROR('Data Sheet'!E58,0) -> 57915.01 | G53: =IFERROR('Data Sheet'!F58,0) -> 64044.04 | H53: =IFERROR('Data Sheet'!G58,0) -> 59116.46 | I53: =IFERROR('Data Sheet'!H58,0) -> 61223.24 | J53: =IFERROR('Data Sheet'!I58,0) -> 67912.46 | ... M53: =IFERROR('Data Sheet'!L58,0) -> 0
B54: Borrowings | C54: =IFERROR('Data Sheet'!B59,0) -> 83.78 | D54: =IFERROR('Data Sheet'!C59,0) -> 45.72 | E54: =IFERROR('Data Sheet'!D59,0) -> 35.92 | F54: =IFERROR('Data Sheet'!E59,0) -> 13.44 | G54: =IFERROR('Data Sheet'!F59,0) -> 277.45 | H54: =IFERROR('Data Sheet'!G59,0) -> 270.83 | I54: =IFERROR('Data Sheet'!H59,0) -> 249.44 | J54: =IFERROR('Data Sheet'!I59,0) -> 306.04 | ... M54: =IFERROR('Data Sheet'!L59,0) -> 0
B55: Other Liabilities | C55: =IFERROR('Data Sheet'!B60,0) -> 8888.04 | D55: =IFERROR('Data Sheet'!C60,0) -> 9439.67 | E55: =IFERROR('Data Sheet'!D60,0) -> 11694.85 | F55: =IFERROR('Data Sheet'!E60,0) -> 12584.73 | G55: =IFERROR('Data Sheet'!F60,0) -> 11760.04 | H55: =IFERROR('Data Sheet'!G60,0) -> 13142.59 | I55: =IFERROR('Data Sheet'!H60,0) -> 14491.01 | J55: =IFERROR('Data Sheet'!I60,0) -> 16369.66 | ... M55: =IFERROR('Data Sheet'!L60,0) -> 0
B56: Total Liabilities | C56: =SUM(C52:C55) -> 51651.34 | D56: =SUM(D52:D55) -> 55898.32 | E56: =SUM(E52:E55) -> 64240.88 | F56: =SUM(F52:F55) -> 71739.04 | G56: =SUM(G52:G55) -> 77310.75 | H56: =SUM(H52:H55) -> 73760.76 | I56: =SUM(I52:I55) -> 77196.02 | J56: =SUM(J52:J55) -> 85830.96 | ... M56: =SUM(M52:M55) -> 0
B58: Fixed Asset Net Block | C58: =IFERROR('Data Sheet'!B62,0) -> 15106.63 | D58: =IFERROR('Data Sheet'!C62,0) -> 15893.48 | E58: =IFERROR('Data Sheet'!D62,0) -> 16523.96 | F58: =IFERROR('Data Sheet'!E62,0) -> 19374.19 | G58: =IFERROR('Data Sheet'!F62,0) -> 21713.34 | H58: =IFERROR('Data Sheet'!G62,0) -> 23298.48 | I58: =IFERROR('Data Sheet'!H62,0) -> 24231.59 | J58: =IFERROR('Data Sheet'!I62,0) -> 25851.27 | ... M58: =IFERROR('Data Sheet'!L62,0) -> 0
B59: Capital Work in Progress | C59: =IFERROR('Data Sheet'!B63,0) -> 2559.72 | D59: =IFERROR('Data Sheet'!C63,0) -> 3729.89 | E59: =IFERROR('Data Sheet'!D63,0) -> 5508.33 | F59: =IFERROR('Data Sheet'!E63,0) -> 4136.42 | G59: =IFERROR('Data Sheet'!F63,0) -> 3256.46 | H59: =IFERROR('Data Sheet'!G63,0) -> 4011.29 | I59: =IFERROR('Data Sheet'!H63,0) -> 3225.54 | J59: =IFERROR('Data Sheet'!I63,0) -> 3003.3 | ... M59: =IFERROR('Data Sheet'!L63,0) -> 0
B60: Investments | C60: =IFERROR('Data Sheet'!B64,0) -> 11747.59 | D60: =IFERROR('Data Sheet'!C64,0) -> 17581.38 | E60: =IFERROR('Data Sheet'!D64,0) -> 22052.86 | F60: =IFERROR('Data Sheet'!E64,0) -> 25043.49 | G60: =IFERROR('Data Sheet'!F64,0) -> 28663.35 | H60: =IFERROR('Data Sheet'!G64,0) -> 24870.87 | I60: =IFERROR('Data Sheet'!H64,0) -> 24841.01 | J60: =IFERROR('Data Sheet'!I64,0) -> 29415.02 | ... M60: =IFERROR('Data Sheet'!L64,0) -> 0
...

Sheet Ratio Analysis
B2: ="Ratio Analysis "&"- "&'Data Sheet'!$B$1 -> Ratio Analysis - ITC LTD
B3: Years | C3: ='Data Sheet'!B16 -> 42460 | D3: ='Data Sheet'!C16 -> 42825 | E3: ='Data Sheet'!D16 -> 43190 | F3: ='Data Sheet'!E16 -> 43555 | G3: ='Data Sheet'!F16 -> 43921 | H3: ='Data Sheet'!G16 -> 44286 | I3: ='Data Sheet'!H16 -> 44651 | J3: ='Data Sheet'!I16 -> 45016 | ... L3: ='Data Sheet'!K16 -> 45747 | M3: Trend | N3: Mean | O3: Median
B4: Sales Growth | C4: ='Historical FS'!C8 -> - | D4: =IFERROR('Historical FS'!D8,0) -> 0.09123012 | E4: =IFERROR('Historical FS'!E8,0) -> 0.015931219 | F4: =IFERROR('Historical FS'!F8,0) -> 0.11256063 | G4: =IFERROR('Historical FS'!G8,0) -> 0.021682439 | H4: =IFERROR('Historical FS'!H8,0) -> -0.0026372963 | I4: =IFERROR('Historical FS'!I8,0) -> 0.23117498 | J4: =IFERROR('Historical FS'!J8,0) -> 0.16942152 | K4: =IFERROR('Historical FS'!K8,0) -> -0.042119724 | L4: =IFERROR('Historical FS'!L8,0) -> 0.10880596 | N4: =AVERAGE(D4:L4) -> 0.078449983 | O4: =MEDIAN(D4:L4) -> 0.09123012
B5: EBITDA Growth | C5: - | D5: =IFERROR('Historical FS'!D19/'Historical FS'!C19-1,0) -> 0.064550848 | E5: =IFERROR('Historical FS'!E19/'Historical FS'!D19-1,0) -> 0.067945268 | F5: =IFERROR('Historical FS'!F19/'Historical FS'!E19-1,0) -> 0.12207796 | G5: =IFERROR('Historical FS'!G19/'Historical FS'!F19-1,0) -> 0.043487783 | H5: =IFERROR('Historical FS'!H19/'Historical FS'!G19-1,0) -> -0.1178047 | I5: =IFERROR('Historical FS'!I19/'Historical FS'!H19-1,0) -> 0.20852129 | J5: =IFERROR('Historical FS'!J19/'Historical FS'!I19-1,0) -> 0.24637895 | K5: =IFERROR('Historical FS'!K19/'Historical FS'!J19-1,0) -> -0.020102893 | L5: =IFERROR('Historical FS'!L19/'Historical FS'!K19-1,0) -> 0.025882649 | N5: =AVERAGE(D5:L5) -> 0.07121524 | O5: =MEDIAN(D5:L5) -> 0.064550848
B6: EBIT Growth | C6: - | D6: =IFERROR('Historical FS'!D25/'Historical FS'!C25-1,0) -> 0.064116562 | E6: =IFERROR('Historical FS'!E25/'Historical FS'!D25-1,0) -> 0.067584614 | F6: =IFERROR('Historical FS'!F25/'Historical FS'!E25-1,0) -> 0.12146247 | G6: =IFERROR('Historical FS'!G25/'Historical FS'!F25-1,0) -> 0.032545193 | H6: =IFERROR('Historical FS'!H25/'Historical FS'!G25-1,0) -> -0.12879189 | I6: =IFERROR('Historical FS'!I25/'Historical FS'!H25-1,0) -> 0.22514477 | J6: =IFERROR('Historical FS'!J25/'Historical FS'!I25-1,0) -> 0.26491869 | K6: =IFERROR('Historical FS'!K25/'Historical FS'!J25-1,0) -> -0.0094483213 | L6: =IFERROR('Historical FS'!L25/'Historical FS'!K25-1,0) -> 0.022123426 | N6: =AVERAGE(D6:L6) -> 0.073295057 | O6: =MEDIAN(D6:L6) -> 0.064116562
B7: Net Profit Growth | C7: - | D7: =IFERROR('Historical FS'!D37/'Historical FS'!C37-1,0) -> 0.087412304 | E7: =IFERROR('Historical FS'!E37/'Historical FS'!D37-1,0) -> 0.061279334 | F7: =IFERROR('Historical FS'!F37/'Historical FS'!E37-1,0) -> 0.16239178 | G7: =IFERROR('Historical FS'!G37/'Historical FS'!F37-1,0) -> 0.225002 | H7: =IFERROR('Historical FS'!H37/'Historical FS'!G37-1,0) -> -0.1798442 | I7: =IFERROR('Historical FS'!I37/'Historical FS'!H37-1,0) -> 0.25795836 | J7: =IFERROR('Historical FS'!J37/'Historical FS'!I37-1,0) -> 0.27849303 | K7: =IFERROR('Historical FS'!K37/'Historical FS'!J37-1,0) -> 0.0024069168 | L7: =IFERROR('Historical FS'!L37/'Historical FS'!K37-1,0) -> -0.0093743668 | N7: =AVERAGE(D7:L7) -> 0.098413907 | O7: =MEDIAN(D7:L7) -> 0.087412304
B8: Dividend Growth | C8: - | D8: =IFERROR('Historical FS'!D45/'Historical FS'!C45-1,0) -> -0.15644462 | E8: =IFERROR('Historical FS'!E45/'Historical FS'!D45-1,0) -> 0.089287385 | F8: =IFERROR('Historical FS'!F45/'Historical FS'!E45-1,0) -> 0.12147406 | G8: =IFERROR('Historical FS'!G45/'Historical FS'!F45-1,0) -> 0.77005405 | H8: =IFERROR('Historical FS'!H45/'Historical FS'!G45-1,0) -> 0.060543835 | I8: =IFERROR('Historical FS'!I45/'Historical FS'!H45-1,0) -> 0.071028026 | J8: =IFERROR('Historical FS'!J45/'Historical FS'!I45-1,0) -> 0.35927687 | K8: =IFERROR('Historical FS'!K45/'Historical FS'!J45-1,0) -> -0.10885617 | L8: =IFERROR('Historical FS'!L45/'Historical FS'!K45-1,0) -> 0.046093953 | N8: =AVERAGE(D8:L8) -> 0.13916193 | O8: =MEDIAN(D8:L8) -> 0.071028026
B10: Gross Margin | C10: =IFERROR('Historical FS'!C14,0) -> 0.59884849 | D10: =IFERROR('Historical FS'!D14,0) -> 0.57169937 | E10: =IFERROR('Historical FS'!E14,0) -> 0.58096561 | F10: =IFERROR('Historical FS'!F14,0) -> 0.58547282 | G10: =IFERROR('Historical FS'!G14,0) -> 0.59434009 | H10: =IFERROR('Historical FS'!H14,0) -> 0.54487737 | I10: =IFERROR('Historical FS'!I14,0) -> 0.5191239 | J10: =IFERROR('Historical FS'!J14,0) -> 0.54080153 | ... L10: =IFERROR('Historical FS'!L14,0) -> 0.53136133 | N10: =AVERAGE(C10:L10) -> 0.56241429 | O10: =MEDIAN(C10:L10) -> 0.5641759
B11: EBITDA Margin | C11: =IFERROR('Historical FS'!C20,0) -> 0.370776 | D11: =IFERROR('Historical FS'!D20,0) -> 0.36171097 | E11: =IFERROR('Historical FS'!E20,0) -> 0.38022999 | F11: =IFERROR('Historical FS'!F20,0) -> 0.38348265 | G11: =IFERROR('Historical FS'!G20,0) -> 0.39166716 | H11: =IFERROR('Historical FS'!H20,0) -> 0.34644059 | I11: =IFERROR('Historical FS'!I20,0) -> 0.34006606 | J11: =IFERROR('Historical FS'!J20,0) -> 0.36244517 | ... L11: =IFERROR('Historical FS'!L20,0) -> 0.34304706 | N11: =AVERAGE(C11:L11) -> 0.36506416 | O11: =MEDIAN(C11:L11) -> 0.36661056
B12: EBIT Margin | C12: =IFERROR('Historical FS'!C26,0) -> 0.34328576 | D12: =IFERROR('Historical FS'!D26,0) -> 0.33475622 | E12: =IFERROR('Historical FS'!E26,0) -> 0.35177636 | F12: =IFERROR('Historical FS'!F26,0) -> 0.354591 | G12: =IFERROR('Historical FS'!G26,0) -> 0.35836109 | H12: =IFERROR('Historical FS'!H26,0) -> 0.31303265 | I12: =IFERROR('Historical FS'!I26,0) -> 0.31149944 | J12: =IFERROR('Historical FS'!J26,0) -> 0.33693707 | ... L12: =IFERROR('Historical FS'!L26,0) -> 0.32119035 | N12: =AVERAGE(C12:L12) -> 0.33738593 | O12: =MEDIAN(C12:L12) -> 0.34011142
B13: EBT Margin | C13: =IFERROR('Historical FS'!C32,0) -> 0.34129225 | D13: =IFERROR('Historical FS'!D32,0) -> 0.33360979 | E13: =IFERROR('Historical FS'!E32,0) -> 0.34912935 | F13: =IFERROR('Historical FS'!F32,0) -> 0.35311395 | G13: =IFERROR('Historical FS'!G32,0) -> 0.35671331 | H13: =IFERROR('Historical FS'!H32,0) -> 0.31185577 | I13: =IFERROR('Historical FS'!I32,0) -> 0.31051023 | J13: =IFERROR('Historical FS'!J32,0) -> 0.33584046 | ... L13: =IFERROR('Historical FS'!L32,0) -> 0.32059213 | N13: =AVERAGE(C13:L13) -> 0.33605108 | O13: =MEDIAN(C13:L13) -> 0.33856636
B14: Net Profit Margin | C14: =IFERROR('Historical FS'!C38,0) -> 0.20457567 | D14: =IFERROR('Historical FS'!D38,0) -> 0.20385993 | E14: =IFERROR('Historical FS'!E38,0) -> 0.21295963 | F14: =IFERROR('Historical FS'!F38,0) -> 0.222498 | G14: =IFERROR('Historical FS'!G38,0) -> 0.26677614 | H14: =IFERROR('Historical FS'!H38,0) -> 0.21937656 | I14: =IFERROR('Historical FS'!I38,0) -> 0.22414895 | J14: =IFERROR('Historical FS'!J38,0) -> 0.24505524 | ... L14: =IFERROR('Historical FS'!L38,0) -> 0.22911358 | N14: =AVERAGE(C14:L14) -> 0.22848102 | O14: =MEDIAN(C14:L14) -> 0.22332348
B16: Sales Expenses %sales | C16: =IFERROR('Historical FS'!C17,0) -> 0.22807249 | D16: =IFERROR('Historical FS'!D17,0) -> 0.2099884 | E16: =IFERROR('Historical FS'!E17,0) -> 0.20073562 | F16: =IFERROR('Historical FS'!F17,0) -> 0.20199017 | G16: =IFERROR('Historical FS'!G17,0) -> 0.20267293 | H16: =IFERROR('Historical FS'!H17,0) -> 0.19843678 | I16: =IFERROR('Historical FS'!I17,0) -> 0.17905783 | J16: =IFERROR('Historical FS'!J17,0) -> 0.17835636 | ... L16: =IFERROR('Historical FS'!L17,0) -> 0.18831427 | N16: =AVERAGE(C16:L16) -> 0.19735014 | O16: =MEDIAN(C16:L16) -> 0.1995862
B17: Depreciation %sales | C17: =IFERROR('Historical FS'!C23,0) -> 0.027490234 | D17: =IFERROR('Historical FS'!D23,0) -> 0.026954751 | E17: =IFERROR('Historical FS'!E23,0) -> 0.028453629 | F17: =IFERROR('Historical FS'!F23,0) -> 0.028891645 | G17: =IFERROR('Historical FS'!G23,0) -> 0.033306066 | H17: =IFERROR('Historical FS'!H23,0) -> 0.033407941 | I17: =IFERROR('Historical FS'!I23,0) -> 0.028566628 | J17: =IFERROR('Historical FS'!J23,0) -> 0.025508104 | ... L17: =IFERROR('Historical FS'!L23,0) -> 0.021856705 | N17: =AVERAGE(C17:L17) -> 0.027678233 | O17: =MEDIAN(C17:L17) -> 0.027971931
B18: Operating Income %Sales | C18: =IFERROR('Historical FS'!C14,0) -> 0.59884849 | D18: =IFERROR('Historical FS'!D14,0) -> 0.57169937 | E18: =IFERROR('Historical FS'!E14,0) -> 0.58096561 | F18: =IFERROR('Historical FS'!F14,0) -> 0.58547282 | G18: =IFERROR('Historical FS'!G14,0) -> 0.59434009 | H18: =IFERROR('Historical FS'!H14,0) -> 0.54487737 | I18: =IFERROR('Historical FS'!I14,0) -> 0.5191239 | J18: =IFERROR('Historical FS'!J14,0) -> 0.54080153 | ... L18: =IFERROR('Historical FS'!L14,0) -> 0.53136133 | N18: =AVERAGE(C18:L18) -> 0.56241429 | O18: =MEDIAN(C18:L18) -> 0.5641759
B20: Return on Capital Employed | C20: =IFERROR('Historical FS'!C25/SUM('Historical FS'!C52:C54),0) -> 0.31461767 | D20: =IFERROR('Historical FS'!D25/SUM('Historical FS'!D52:D54),0) -> 0.30816048 | E20: =IFERROR('Historical FS'!E25/SUM('Historical FS'!E52:E54),0) -> 0.29087469 | F20: =IFERROR('Historical FS'!F25/SUM('Historical FS'!F52:F54),0) -> 0.28976384 | G20: =IFERROR('Historical FS'!G25/SUM('Historical FS'!G52:G54),0) -> 0.26999906 | H20: =IFERROR('Historical FS'!H25/SUM('Historical FS'!H52:H54),0) -> 0.25436581 | I20: =IFERROR('Historical FS'!I25/SUM('Historical FS'!I52:I54),0) -> 0.30126365 | J20: =IFERROR('Historical FS'!J25/SUM('Historical FS'!J52:J54),0) -> 0.3440081 | ... L20: =IFERROR('Historical FS'!L25/SUM('Historical FS'!L52:L54),0) -> 0.34406984 | N20: =AVERAGE(C20:L20) -> 0.30335159 | O20: =MEDIAN(C20:L20) -> 0.30471206
B21: Retained Earnings% | C21: =IFERROR('Historical FS'!C48,0) -> 0.14687786 | D21: =IFERROR('Historical FS'!D48,0) -> 0.33819421 | E21: =IFERROR('Historical FS'!E48,0) -> 0.3207286 | F21: =IFERROR('Historical FS'!F48,0) -> 0.34463984 | G21: =IFERROR('Historical FS'!G48,0) -> 0.053044068 | H21: =IFERROR('Historical FS'!H48,0) -> 0 | I21: =IFERROR('Historical FS'!I48,0) -> 0 | J21: =IFERROR('Historical FS'!J48,0) -> 0 | ... L21: =IFERROR('Historical FS'!L48,0) -> 0 | N21: =AVERAGE(C21:L21) -> 0.12180906 | O21: =MEDIAN(C21:L21) -> 0.03382504
B22: Return on Equity% | C22: =IFERROR('Historical FS'!C37/SUM('Historical FS'!C52:C53),0) -> 0.18785942 | D22: =IFERROR('Historical FS'!D37/SUM('Historical FS'!D52:D53),0) -> 0.18784852 | E22: =IFERROR('Historical FS'!E37/SUM('Historical FS'!E52:E53),0) -> 0.17621121 | F22: =IFERROR('Historical FS'!F37/SUM('Historical FS'!F52:F53),0) -> 0.18186171 | G22: =IFERROR('Historical FS'!G37/SUM('Historical FS'!G52:G53),0) -> 0.2018508 | H22: =IFERROR('Historical FS'!H37/SUM('Historical FS'!H52:H53),0) -> 0.17906224 | I22: =IFERROR('Historical FS'!I37/SUM('Historical FS'!I52:I53),0) -> 0.21764928 | J22: =IFERROR('Historical FS'!J37/SUM('Historical FS'!J52:J53),0) -> 0.25130525 | ... L22: =IFERROR('Historical FS'!L37/SUM('Historical FS'!L52:L53),0) -> 0.24643135 | N22: =AVERAGE(C22:L22) -> 0.20638955 | O22: =MEDIAN(C22:L22) -> 0.19485511
B23: Self Sustained Growth Rate | C23: =IFERROR(C21*C22,0) -> 0.027592391 | D23: =IFERROR(D21*D22,0) -> 0.063529279 | E23: =IFERROR(E21*E22,0) -> 0.056515974 | F23: =IFERROR(F21*F22,0) -> 0.062676792 | G23: =IFERROR(G21*G22,0) -> 0.010706988 | H23: =IFERROR(H21*H22,0) -> 0 | I23: =IFERROR(I21*I22,0) -> 0 | J23: =IFERROR(J21*J22,0) -> 0 | ... L23: =IFERROR(L21*L22,0) -> 0 | N23: =AVERAGE(C23:L23) -> 0.022443654 | O23: =MEDIAN(C23:L23) -> 0.0070610516
B24: Interest Coverage Ratio | C24: =IFERROR('Historical FS'!C25/'Historical FS'!C28,0) -> 172.20133 | D24: =IFERROR('Historical FS'!D25/'Historical FS'!D28,0) -> 291.99918 | E24: =IFERROR('Historical FS'!E25/'Historical FS'!E28,0) -> 132.89549 | F24: =IFERROR('Historical FS'!F25/'Historical FS'!F28,0) -> 240.06695 | G24: =IFERROR('Historical FS'!G25/'Historical FS'!G28,0) -> 217.48132 | H24: =IFERROR('Historical FS'!H25/'Historical FS'!H28,0) -> 265.98568 | I24: =IFERROR('Historical FS'!I25/'Historical FS'!I28,0) -> 314.89815 | J24: =IFERROR('Historical FS'!J25/'Historical FS'!J28,0) -> 307.25537 | ... L24: =IFERROR('Historical FS'!L25/'Historical FS'!L28,0) -> 536.90923 | N24: =AVERAGE(C24:L24) -> 308.48955 | O24: =MEDIAN(C24:L24) -> 278.99243
B26: Debtor Turnover Ratio | C26: =IFERROR('Historical FS'!C7/'Raw FS'!E14,0) -> 16.755921 | D26: =IFERROR('Historical FS'!D7/'Raw FS'!F14,0) -> 16.084092 | E26: =IFERROR('Historical FS'!E7/'Raw FS'!G14,0) -> 12.428186 | F26: =IFERROR('Historical FS'!F7/'Raw FS'!H14,0) -> 13.77196 | G26: =IFERROR('Historical FS'!G7/'Raw FS'!I14,0) -> 13.605427 | H26: =IFERROR('Historical FS'!H7/'Raw FS'!J14,0) -> 11.404828 | I26: =IFERROR('Historical FS'!I7/'Raw FS'!K14,0) -> 13.729803 | J26: =IFERROR('Historical FS'!J7/'Raw FS'!L14,0) -> 15.221942 | ... L26: =IFERROR('Historical FS'!L7/'Raw FS'!N14,0) -> 15.669511 | N26: =AVERAGE(C26:L26) -> 14.283006 | O26: =MEDIAN(C26:L26) -> 13.965173
B27: Creditor Turnover Ratio | C27: =IFERROR('Historical FS'!C7/'Historical FS'!C64,0) -> 20.442577 | D27: =IFERROR('Historical FS'!D7/'Historical FS'!D64,0) -> 17.284797 | E27: =IFERROR('Historical FS'!E7/'Historical FS'!E64,0) -> 16.19845 | F27: =IFERROR('Historical FS'!F7/'Historical FS'!F64,0) -> 11.979238 | G27: =IFERROR('Historical FS'!G7/'Historical FS'!G64,0) -> 19.273399 | H27: =IFERROR('Historical FS'!H7/'Historical FS'!H64,0) -> 19.689591 | I27: =IFERROR('Historical FS'!I7/'Historical FS'!I64,0) -> 24.633226 | J27: =IFERROR('Historical FS'!J7/'Historical FS'!J64,0) -> 23.990173 | ... L27: =IFERROR('Historical FS'!L7/'Historical FS'!L64,0) -> 15.959451 | N27: =AVERAGE(C27:L27) -> 18.632497 | O27: =MEDIAN(C27:L27) -> 18.279098
B28: Inventory Turnover | C28: =IFERROR('Historical FS'!C7/'Historical FS'!C65,0) -> 4.3248364 | D28: =IFERROR('Historical FS'!D7/'Historical FS'!D65,0) -> 5.2694767 | E28: =IFERROR('Historical FS'!E7/'Historical FS'!E65,0) -> 5.7969871 | F28: =IFERROR('Historical FS'!F7/'Historical FS'!F65,0) -> 6.1504181 | G28: =IFERROR('Historical FS'!G7/'Historical FS'!G65,0) -> 5.5620976 | H28: =IFERROR('Historical FS'!H7/'Historical FS'!H65,0) -> 4.737587 | I28: =IFERROR('Historical FS'!I7/'Historical FS'!I65,0) -> 5.5820787 | J28: =IFERROR('Historical FS'!J7/'Historical FS'!J65,0) -> 6.0248123 | ... L28: =IFERROR('Historical FS'!L7/'Historical FS'!L65,0) -> 4.8168218 | N28: =AVERAGE(C28:L28) -> 5.3064983 | O28: =MEDIAN(C28:L28) -> 5.4157872
B29: Fixed Asset Turnover | C29: =IFERROR('Historical FS'!C7/'Historical FS'!C58,0) -> 2.5943642 | D29: =IFERROR('Historical FS'!D7/'Historical FS'!D58,0) -> 2.6908896 | E29: =IFERROR('Historical FS'!E7/'Historical FS'!E58,0) -> 2.6294508 | F29: =IFERROR('Historical FS'!F7/'Historical FS'!F58,0) -> 2.4950504 | G29: =IFERROR('Historical FS'!G7/'Historical FS'!G58,0) -> 2.2745326 | H29: =IFERROR('Historical FS'!H7/'Historical FS'!H58,0) -> 2.1141916 | I29: =IFERROR('Historical FS'!I7/'Historical FS'!I58,0) -> 2.5027058 | J29: =IFERROR('Historical FS'!J7/'Historical FS'!J58,0) -> 2.743348 | ... L29: =IFERROR('Historical FS'!L7/'Historical FS'!L58,0) -> 3.4308292 | N29: =AVERAGE(C29:L29) -> 2.5917181 | O29: =MEDIAN(C29:L29) -> 2.548535
B30: Capital Turnover Ratio | C30: =IFERROR('Historical FS'!C7/SUM('Historical FS'!C52:C53),0) -> 0.91828821 | D30: =IFERROR('Historical FS'!D7/SUM('Historical FS'!D52:D53),0) -> 0.92145874 | E30: =IFERROR('Historical FS'!E7/SUM('Historical FS'!E52:E53),0) -> 0.82743952 | F30: =IFERROR('Historical FS'!F7/SUM('Historical FS'!F52:F53),0) -> 0.81736336 | G30: =IFERROR('Historical FS'!G7/SUM('Historical FS'!G52:G53),0) -> 0.7566299 | H30: =IFERROR('Historical FS'!H7/SUM('Historical FS'!H52:H53),0) -> 0.81623233 | I30: =IFERROR('Historical FS'!I7/SUM('Historical FS'!I52:I53),0) -> 0.97100291 | J30: =IFERROR('Historical FS'!J7/SUM('Historical FS'!J52:J53),0) -> 1.0255045 | ... L30: =IFERROR('Historical FS'!L7/SUM('Historical FS'!L52:L53),0) -> 1.075586 | N30: =AVERAGE(C30:L30) -> 0.90412579 | O30: =MEDIAN(C30:L30) -> 0.91502033
B32: (in days)
B33: Debtor Days | C33: =IFERROR(365/C26,0) -> 21.783344 | D33: =IFERROR(365/D26,0) -> 22.69323 | E33: =IFERROR(365/E26,0) -> 29.368726 | F33: =IFERROR(365/F26,0) -> 26.503126 | G33: =IFERROR(365/G26,0) -> 26.82753 | H33: =IFERROR(365/H26,0) -> 32.003991 | I33: =IFERROR(365/I26,0) -> 26.584504 | J33: =IFERROR(365/J26,0) -> 23.978543 | ... L33: =IFERROR(365/L26,0) -> 23.293643 | N33: =AVERAGE(C33:L33) -> 25.881641 | O33: =MEDIAN(C33:L33) -> 26.14145
B34: Payable Days | C34: =IFERROR(365/C27,0) -> 17.854892 | D34: =IFERROR(365/D27,0) -> 21.116823 | E34: =IFERROR(365/E27,0) -> 22.53302 | F34: =IFERROR(365/F27,0) -> 30.469383 | G34: =IFERROR(365/G27,0) -> 18.938019 | H34: =IFERROR(365/H27,0) -> 18.537714 | I34: =IFERROR(365/I27,0) -> 14.817385 | J34: =IFERROR(365/J27,0) -> 15.214563 | ... L34: =IFERROR(365/L27,0) -> 22.870462 | N34: =AVERAGE(C34:L34) -> 20.398309 | O34: =MEDIAN(C34:L34) -> 20.027421
B35: Inventory Days | C35: =IFERROR(365/C28,0) -> 84.396256 | D35: =IFERROR(365/D28,0) -> 69.26684 | E35: =IFERROR(365/E28,0) -> 62.963742 | F35: =IFERROR(365/F28,0) -> 59.345559 | G35: =IFERROR(365/G28,0) -> 65.622725 | H35: =IFERROR(365/H28,0) -> 77.04344 | I35: =IFERROR(365/I28,0) -> 65.387828 | J35: =IFERROR(365/J28,0) -> 60.5828 | ... L35: =IFERROR(365/L28,0) -> 75.776106 | N35: =AVERAGE(C35:L35) -> 69.642907 | O35: =MEDIAN(C35:L35) -> 67.444782
B36: Cash Conversion Days | C36: =SUM(C33,C35)-C34 -> 88.324708 | D36: =SUM(D33,D35)-D34 -> 70.843247 | E36: =SUM(E33,E35)-E34 -> 69.799447 | F36: =SUM(F33,F35)-F34 -> 55.379302 | G36: =SUM(G33,G35)-G34 -> 73.512236 | H36: =SUM(H33,H35)-H34 -> 90.509718 | I36: =SUM(I33,I35)-I34 -> 77.154947 | J36: =SUM(J33,J35)-J34 -> 69.34678 | ... L36: =SUM(L33,L35)-L34 -> 76.199288 | N36: =AVERAGE(C36:L36) -> 75.126239 | O36: =MEDIAN(C36:L36) -> 74.855762
B38: CFO/Sales | C38: =IFERROR('Historical FS'!C75/'Historical FS'!C7,0) -> 0.2500259 | D38: =IFERROR('Historical FS'!D75/'Historical FS'!D7,0) -> 0.24848974 | E38: =IFERROR('Historical FS'!E75/'Historical FS'!E7,0) -> 0.3031006 | F38: =IFERROR('Historical FS'!F75/'Historical FS'!F7,0) -> 0.26031277 | G38: =IFERROR('Historical FS'!G75/'Historical FS'!G7,0) -> 0.2974356 | H38: =IFERROR('Historical FS'!H75/'Historical FS'!H7,0) -> 0.25431625 | I38: =IFERROR('Historical FS'!I75/'Historical FS'!I7,0) -> 0.26013076 | J38: =IFERROR('Historical FS'!J75/'Historical FS'!J7,0) -> 0.26618455 | ... L38: =IFERROR('Historical FS'!L75/'Historical FS'!L7,0) -> 0.2340183 | N38: =AVERAGE(C38:L38) -> 0.26268979 | O38: =MEDIAN(C38:L38) -> 0.2572235
B39: CFO/Total Assets | C39: =IFERROR('Historical FS'!C75/'Historical FS'!C69,0) -> 0.18971512 | D39: =IFERROR('Historical FS'!D75/'Historical FS'!D69,0) -> 0.19011859 | E39: =IFERROR('Historical FS'!E75/'Historical FS'!E69,0) -> 0.20500031 | F39: =IFERROR('Historical FS'!F75/'Historical FS'!F69,0) -> 0.17540533 | G39: =IFERROR('Historical FS'!G75/'Historical FS'!G69,0) -> 0.19000799 | H39: =IFERROR('Historical FS'!H75/'Historical FS'!H69,0) -> 0.16983244 | I39: =IFERROR('Historical FS'!I75/'Historical FS'!I69,0) -> 0.20435652 | J39: =IFERROR('Historical FS'!J75/'Historical FS'!J69,0) -> 0.2199387 | ... L39: =IFERROR('Historical FS'!L75/'Historical FS'!L69,0) -> 0.20030113 | N39: =AVERAGE(C39:L39) -> 0.19319036 | O39: =MEDIAN(C39:L39) -> 0.19006329
B40: CFO/Total Debt | C40: =IFERROR('Historical FS'!C75/'Historical FS'!C54,0) -> 116.96157 | D40: =IFERROR('Historical FS'!D75/'Historical FS'!D54,0) -> 232.44335 | E40: =IFERROR('Historical FS'!E75/'Historical FS'!E54,0) -> 366.6314 | F40: =IFERROR('Historical FS'!F75/'Historical FS'!F54,0) -> 936.26562 | G40: =IFERROR('Historical FS'!G75/'Historical FS'!G54,0) -> 52.945251 | H40: =IFERROR('Historical FS'!H75/'Historical FS'!H54,0) -> 46.253997 | I40: =IFERROR('Historical FS'!I75/'Historical FS'!I54,0) -> 63.243706 | J40: =IFERROR('Historical FS'!J75/'Historical FS'!J54,0) -> 61.683277 | ... L40: =IFERROR('Historical FS'!L75/'Historical FS'!L54,0) -> 61.949251 | N40: =AVERAGE(C40:L40) -> 199.4993 | O40: =MEDIAN(C40:L40) -> 62.596479

Sheet Forecast
B2: ='Data Sheet'!B1&" - "&'Data Sheet'!A17&" Forecast" -> ITC LTD - Sales Forecast | G2: ='Data Sheet'!B1&" - "&'Historical FS'!B19&" Forecast" -> ITC LTD - EBITDA Forecast | L2: ='Data Sheet'!B1&" - "&'Historical FS'!B42&" Forecast" -> ITC LTD - Earnings Per Share Forecast
B3: Year Weight | C3: Year | D3: Sales | E3: Sales Growth | G3: Year Weight | H3: Year | I3: EBITDA | J3: EBITDA Growth | L3: Year Weight | M3: Year | N3: EPS | O3: EPS Growth
B4: 1 | C4: {=TRANSPOSE('Data Sheet'!B16:K16)} -> 42460 | D4: {=TRANSPOSE('Historical FS'!C7:L7)} -> 39192.1 | G4: 1 | H4: {=TRANSPOSE('Data Sheet'!B16:K16)} -> 42460 | I4: {=TRANSPOSE('Historical FS'!C19:L19)} -> 14531.49 | L4: 1 | M4: {=TRANSPOSE('Data Sheet'!B16:K16)} -> 42460 | N4: {=TRANSPOSE('Historical FS'!C42:L42)} -> 6.3991147
B5: 2 | C5: 42825 | D5: 42767.6 | E5: =IFERROR(D5/D4-1,0) -> 0.09123012 | G5: 2 | H5: 42825 | I5: 15469.51 | J5: =IFERROR(I5/I4-1,0) -> 0.064550848 | L5: 2 | M5: 42825 | N5: 6.958476 | O5: =IFERROR(N5/N4-1,0) -> 0.087412304
B6: 3 | C6: 43190 | D6: 43448.94 | E6: =IFERROR(D6/D5-1,0) -> 0.015931219 | G6: 3 | H6: 43190 | I6: 16520.59 | J6: =IFERROR(I6/I5-1,0) -> 0.067945268 | L6: 3 | M6: 43190 | N6: 7.3848868 | O6: =IFERROR(N6/N5-1,0) -> 0.061279334
B7: 4 | C7: 43555 | D7: 48339.58 | E7: =IFERROR(D7/D6-1,0) -> 0.11256063 | G7: 4 | H7: 43555 | I7: 18537.39 | J7: =IFERROR(I7/I6-1,0) -> 0.12207796 | L7: 4 | M7: 43555 | N7: 8.5841317 | O7: =IFERROR(N7/N6-1,0) -> 0.16239178
B8: 5 | C8: 43921 | D8: 49387.7 | E8: =IFERROR(D8/D7-1,0) -> 0.021682439 | G8: 5 | H8: 43921 | I8: 19343.54 | J8: =IFERROR(I8/I7-1,0) -> 0.043487783 | L8: 5 | M8: 43921 | N8: 10.515579 | O8: =IFERROR(N8/N7-1,0) -> 0.225002
B9: 6 | C9: 44286 | D9: 49257.45 | E9: =IFERROR(D9/D8-1,0) -> -0.0026372963 | G9: 6 | H9: 44286 | I9: 17064.78 | J9: =IFERROR(I9/I8-1,0) -> -0.1178047 | L9: 6 | M9: 44286 | N9: 8.6244128 | O9: =IFERROR(N9/N8-1,0) -> -0.1798442
B10: 7 | C10: 44651 | D10: 60644.54 | E10: =IFERROR(D10/D9-1,0) -> 0.23117498 | G10: 7 | H10: 44651 | I10: 20623.15 | J10: =IFERROR(I10/I9-1,0) -> 0.20852129 | L10: 7 | M10: 44651 | N10: 10.849152 | O10: =IFERROR(N10/N9-1,0) -> 0.25795836
B11: 8 | C11: 45016 | D11: 70919.03 | E11: =IFERROR(D11/D10-1,0) -> 0.16942152 | G11: 8 | H11: 45016 | I11: 25704.26 | J11: =IFERROR(I11/I10-1,0) -> 0.24637895 | L11: 8 | M11: 45016 | N11: 13.870565 | O11: =IFERROR(N11/N10-1,0) -> 0.27849303
B12: 9 | C12: 45382 | D12: 67931.94 | E12: =IFERROR(D12/D11-1,0) -> -0.042119724 | G12: 9 | H12: 45382 | I12: 25187.53 | J12: =IFERROR(I12/I11-1,0) -> -0.020102893 | L12: 9 | M12: 45382 | N12: 13.903951 | O12: =IFERROR(N12/N11-1,0) -> 0.0024069168
B13: 10 | C13: 45747 | D13: 75323.34 | E13: =IFERROR(D13/D12-1,0) -> 0.10880596 | G13: 10 | H13: 45747 | I13: 25839.45 | J13: =IFERROR(I13/I12-1,0) -> 0.025882649 | L13: 10 | M13: 45747 | N13: 13.77361 | O13: =IFERROR(N13/N12-1,0) -> -0.0093743668
B14: 11 | C14: =C13+365 -> 46112 | D14: =FORECAST(B14,$D$4:$D$13,$B$4:$B$13) -> 77236.776 | E14: =IFERROR(D14/D13-1,0) -> 0.025402963 | G14: 11 | H14: =H13+365 -> 46112 | I14: =FORECAST(G14,$I$4:$I$13,$G$4:$G$13) -> 27205.324 | J14: =IFERROR(I14/I13-1,0) -> 0.052860026 | L14: 11 | M14: =M13+365 -> 46112 | N14: =FORECAST(L14,$N$4:$N$13,$L$4:$L$13) -> 15.163757 | O14: =IFERROR(N14/N13-1,0) -> 0.10092829
B15: 12 | C15: =C14+365 -> 46477 | D15: =FORECAST(B15,$D$4:$D$13,$B$4:$B$13) -> 81330.513 | E15: =IFERROR(D15/D14-1,0) -> 0.053002434 | G15: 12 | H15: =H14+365 -> 46477 | I15: =FORECAST(G15,$I$4:$I$13,$G$4:$G$13) -> 28536.807 | J15: =IFERROR(I15/I14-1,0) -> 0.048941991 | L15: 12 | M15: =M14+365 -> 46477 | N15: =FORECAST(L15,$N$4:$N$13,$L$4:$L$13) -> 16.086915 | O15: =IFERROR(N15/N14-1,0) -> 0.06087924
B16: 13 | C16: =C15+365 -> 46842 | D16: =FORECAST(B16,$D$4:$D$13,$B$4:$B$13) -> 85424.25 | E16: =IFERROR(D16/D15-1,0) -> 0.050334578 | G16: 13 | H16: =H15+365 -> 46842 | I16: =FORECAST(G16,$I$4:$I$13,$G$4:$G$13) -> 29868.289 | J16: =IFERROR(I16/I15-1,0) -> 0.046658434 | L16: 13 | M16: =M15+365 -> 46842 | N16: =FORECAST(L16,$N$4:$N$13,$L$4:$L$13) -> 17.010073 | O16: =IFERROR(N16/N15-1,0) -> 0.057385646
B17: 14 | C17: =C16+365 -> 47207 | D17: =FORECAST(B17,$D$4:$D$13,$B$4:$B$13) -> 89517.987 | E17: =IFERROR(D17/D16-1,0) -> 0.047922423 | G17: 14 | H17: =H16+365 -> 47207 | I17: =FORECAST(G17,$I$4:$I$13,$G$4:$G$13) -> 31199.772 | J17: =IFERROR(I17/I16-1,0) -> 0.044578473 | L17: 14 | M17: =M16+365 -> 47207 | N17: =FORECAST(L17,$N$4:$N$13,$L$4:$L$13) -> 17.933231 | O17: =IFERROR(N17/N16-1,0) -> 0.054271255
B18: 15 | C18: =C17+365 -> 47572 | D18: =FORECAST(B18,$D$4:$D$13,$B$4:$B$13) -> 93611.724 | E18: =IFERROR(D18/D17-1,0) -> 0.045730888 | G18: 15 | H18: =H17+365 -> 47572 | I18: =FORECAST(G18,$I$4:$I$13,$G$4:$G$13) -> 32531.255 | J18: =IFERROR(I18/I17-1,0) -> 0.04267604 | L18: 15 | M18: =M17+365 -> 47572 | N18: =FORECAST(L18,$N$4:$N$13,$L$4:$L$13) -> 18.856389 | O18: =IFERROR(N18/N17-1,0) -> 0.051477506

Sheet WACC
B2: ="Weighted Average Cost of Capital"&" - "&'Data Sheet'!B1 -> Weighted Average Cost of Capital - ITC LTD
B4: All figures are in INR unless stated otherwise.
B6: Peer comps
G7: Debt / | H7: Debt / | I7: Levered | J7: Unlevered
B8: Name of the comp | C8: Country | D8: Total Debt | E8: Total Equity | F8: Tax rate 1 | G8: Equity | H8: Capital | I8: Beta 2 | J8: Beta 3
B10: ='Peer Comps'!C5 -> ITC | C10: India | D10: =IFERROR('Peer Comps'!F5,0) -> 362.97 | E10: =IFERROR('Peer Comps'!E5,0) -> 387348.51 | F10: =IFERROR('Peer Comps'!I12,0) -> 0.27862226 | G10: =IFERROR(D10/E10,0) -> 0.00093706311 | H10: =IFERROR(D10/(D10+E10),0) -> 0.00093618585 | I10: =IFERROR('Peer Comps'!H5,0) -> 0.515 | J10: =IFERROR(I10/(1+(1-F10)*G10),0) -> 0.51465211
B11: ='Peer Comps'!C4 -> Hind. Unilever | C11: India | D11: =IFERROR('Peer Comps'!F4,0) -> 1775 | E11: =IFERROR('Peer Comps'!E4,0) -> 540705.54 | F11: =IFERROR('Peer Comps'!I13,0) -> 0.2592 | G11: =IFERROR(D11/E11,0) -> 0.0032827479 | H11: =IFERROR(D11/(D11+E11),0) -> 0.0032720068 | I11: =IFERROR('Peer Comps'!H4,0) -> 0.584 | J11: =IFERROR(I11/(1+(1-F11)*G11),0) -> 0.58258324
B12: ='Peer Comps'!C6 -> Nestle India | C12: India | D12: =IFERROR('Peer Comps'!F6,0) -> 444.16 | E12: =IFERROR('Peer Comps'!E6,0) -> 265881.4 | F12: =IFERROR('Peer Comps'!I14,0) -> 0.25904 | G12: =IFERROR(D12/E12,0) -> 0.0016705193 | H12: =IFERROR(D12/(D12+E12),0) -> 0.0016677333 | I12: =IFERROR('Peer Comps'!H6,0) -> 0.751 | J12: =IFERROR(I12/(1+(1-F12)*G12),0) -> 0.75007157
B13: ='Peer Comps'!C7 -> Varun Beverages | C13: India | D13: =IFERROR('Peer Comps'!F7,0) -> 2508.18 | E13: =IFERROR('Peer Comps'!E7,0) -> 164118.16 | F13: =IFERROR('Peer Comps'!I15,0) -> 0.25 | G13: =IFERROR(D13/E13,0) -> 0.015282769 | H13: =IFERROR(D13/(D13+E13),0) -> 0.015052722 | I13: =IFERROR('Peer Comps'!H7,0) -> 1.16 | J13: =IFERROR(I13/(1+(1-F13)*G13),0) -> 1.1468547
B14: ='Peer Comps'!C8 -> Britannia Inds. | C14: India | D14: =IFERROR('Peer Comps'!F8,0) -> 2196.3 | E14: =IFERROR('Peer Comps'!E8,0) -> 140725.16 | F14: =IFERROR('Peer Comps'!I16,0) -> 0.25878 | G14: =IFERROR(D14/E14,0) -> 0.015607017 | H14: =IFERROR(D14/(D14+E14),0) -> 0.015367181 | I14: =IFERROR('Peer Comps'!H8,0) -> 0.51 | J14: =IFERROR(I14/(1+(1-F14)*G14),0) -> 0.50416767
E16: Average | F16: =AVERAGE(F10:F14) -> 0.26112845 | G16: =AVERAGE(G10:G14) -> 0.0073560234 | H16: =AVERAGE(H10:H14) -> 0.0072591659 | I16: =AVERAGE(I10:I14) -> 0.704 | J16: =AVERAGE(J10:J14) -> 0.69966585
E17: Median | F17: =MEDIAN(F10:F14) -> 0.25904 | G17: =MEDIAN(G10:G14) -> 0.0032827479 | H17: =MEDIAN(H10:H14) -> 0.0032720068 | I17: =MEDIAN(I10:I14) -> 0.584 | J17: =MEDIAN(J10:J14) -> 0.58258324
B20: Cost of Debt | G20: Cost of Equity
B22: Pre-Tax Cost of Debt | E22: ='Data Sheet'!K27/WACC!D10 -> 0.12414249 | G22: Risk free Rate | J22: 0.06891
B23: Tax Rate | E23: =F17 -> 0.25904 | G23: Equity Risk Premium | J23: =IFERROR('Return on Market'!F7-WACC!J22,0) -> 0.095382308
B24: Post -Tax Cost of Debt | E24: =E22*(1-E23) -> 0.09198462 | G24: Levered Beta 4 | J24: =J33 -> 0.58400031
G25: Cost of Equity | J25: =J22+(J23*J24) -> 0.1246133
B28: Capital Structure | G28: Capital Structure
D30: Current | E30: Target | G30: Comps Median Unlevered Beta | J30: =J17 -> 0.58258324
B31: Total Debt | C31: =D10 -> 362.97 | D31: =C31/$C$33 -> 0.00093618585 | E31: =H17 -> 0.0032720068 | G31: Target Debt / Equity | J31: =E35 -> 0.0032827479
B32: Market Capitalisation | C32: =E10 -> 387348.51 | D32: =C32/$C$33 -> 0.99906381 | E32: =IFERROR(E33-E31,0) -> 0.99672799 | G32: Tax Rate | J32: =E23 -> 0.25904
B33: Total Capital | C33: =IFERROR(C32+C31,0) -> 387711.48 | D33: =C33/$C$33 -> 1 | E33: =D33 -> 1 | G33: Levered Beta | J33: =J30*(1+(1-J32)*J31) -> 0.58400031
B35: Debt / Equity | D35: =D31/D32 -> 0.00093706311 | E35: =E31/E32 -> 0.0032827479
G36: Weighted Average Cost of Capital
B37: Notes:
B38: 1.Tax rate considered as marginal tax rate of the country. | G38: Cost of Equity | J38: =J25 -> 0.1246133
B39: 2.Levered beta is based on 5 year monthly data | G39: Equity Weight | J39: =E32 -> 0.99672799
B40: 3.Unlevered beta = Levered beta / (1+(1-tax_rate)*Debt / Equity)
B41: 4.Levered beta = Unlevered beta * (1+(1-tax_rate)*Debt / Equity) | G41: Cost of Debt | J41: =E24 -> 0.09198462
G42: Debt Weight | J42: =E31 -> 0.0032720068
G44: WACC | J44: =(J38*J39)+(J41*J42) -> 0.12450654

Sheet Intrinsic Growth
A2: # | B2: Calculation of ROIC | F2: ='Data Sheet'!G16 -> 44286 | G2: ='Data Sheet'!H16 -> 44651 | H2: ='Data Sheet'!I16 -> 45016 | I2: ='Data Sheet'!J16 -> 45382 | J2: ='Data Sheet'!K16 -> 45747
B4: Current assets
B5: ='Raw FS'!B37 -> Inventories | F5: =IFERROR('Raw FS'!J37,0) -> 10397 | G5: =IFERROR('Raw FS'!K37,0) -> 10864 | H5: =IFERROR('Raw FS'!L37,0) -> 11771 | I5: =IFERROR('Raw FS'!M37,0) -> 14153 | J5: =IFERROR('Raw FS'!N37,0) -> 15638
B6: ='Raw FS'!B38 -> Trade receivables | F6: =IFERROR('Raw FS'!J38,0) -> 2502 | G6: =IFERROR('Raw FS'!K38,0) -> 2462 | H6: =IFERROR('Raw FS'!L38,0) -> 2956 | I6: =IFERROR('Raw FS'!M38,0) -> 4026 | J6: =IFERROR('Raw FS'!N38,0) -> 4720
B7: ='Raw FS'!B40 -> Loans n Advances | F7: =IFERROR('Raw FS'!J40,0) -> 7 | G7: =IFERROR('Raw FS'!K40,0) -> 11 | H7: =IFERROR('Raw FS'!L40,0) -> 13 | I7: =IFERROR('Raw FS'!M40,0) -> 31 | J7: =IFERROR('Raw FS'!N40,0) -> 10
B8: ='Raw FS'!B41 -> Other asset items | F8: =IFERROR('Raw FS'!J41,0) -> 4015 | G8: =IFERROR('Raw FS'!K41,0) -> 6906 | H8: =IFERROR('Raw FS'!L41,0) -> 7941 | I8: =IFERROR('Raw FS'!M41,0) -> 4531 | J8: =IFERROR('Raw FS'!N41,0) -> 5858
B9: Total Current Assets | F9: =SUM(F5:F8) -> 16921 | G9: =SUM(G5:G8) -> 20243 | H9: =SUM(H5:H8) -> 22681 | I9: =SUM(I5:I8) -> 22741 | J9: =SUM(J5:J8) -> 26226
B11: Current Liabilities
B12: ='Raw FS'!B14 -> Trade Payables | F12: ='Raw FS'!J14 -> 4319 | G12: ='Raw FS'!K14 -> 4417 | H12: ='Raw FS'!L14 -> 4659 | I12: ='Raw FS'!M14 -> 4798 | J12: ='Raw FS'!N14 -> 4807
B13: ='Raw FS'!B9 -> Short term Borrowings | F13: ='Raw FS'!J9 -> 4 | G13: ='Raw FS'!K9 -> 1 | H13: ='Raw FS'!L9 -> 35 | I13: ='Raw FS'!M9 -> 10 | J13: ='Raw FS'!N9 -> 91
B14: ='Raw FS'!B10 -> Lease Liabilities | F14: ='Raw FS'!J10 -> 261 | G14: ='Raw FS'!K10 -> 244 | H14: ='Raw FS'!L10 -> 267 | I14: ='Raw FS'!M10 -> 292 | J14: ='Raw FS'!N10 -> 193
B15: ='Raw FS'!B15 -> Advance from Customers | F15: ='Raw FS'!J15 -> 811 | G15: ='Raw FS'!K15 -> 1278 | H15: ='Raw FS'!L15 -> 1295 | I15: ='Raw FS'!M15 -> 886 | J15: ='Raw FS'!N15 -> 1264
B16: ='Raw FS'!B16 -> Other liability items | F16: ='Raw FS'!J16 -> 7666 | G16: ='Raw FS'!K16 -> 8429 | H16: ='Raw FS'!L16 -> 10032 | I16: ='Raw FS'!M16 -> 10877 | J16: ='Raw FS'!N16 -> 11249
B17: Total Current Liabilites | F17: =SUM(F12:F16) -> 13061 | G17: =SUM(G12:G16) -> 14369 | H17: =SUM(H12:H16) -> 16288 | I17: =SUM(I12:I16) -> 16863 | J17: =SUM(J12:J16) -> 17604
A19: # | B19: Net Working Capital | F19: =F9-F17 -> 3860 | G19: =G9-G17 -> 5874 | H19: =H9-H17 -> 6393 | I19: =I9-I17 -> 5878 | J19: =J9-J17 -> 8622
B21: Non Current Assets
B22: ='Raw FS'!B20 -> Land | F22: =IFERROR('Raw FS'!J20,0) -> 2889 | G22: =IFERROR('Raw FS'!K20,0) -> 2829 | H22: =IFERROR('Raw FS'!L20,0) -> 2830 | I22: =IFERROR('Raw FS'!M20,0) -> 2865 | J22: =IFERROR('Raw FS'!N20,0) -> 1588
B23: ='Raw FS'!B21 -> Building | F23: =IFERROR('Raw FS'!J21,0) -> 8387 | G23: =IFERROR('Raw FS'!K21,0) -> 9100 | H23: =IFERROR('Raw FS'!L21,0) -> 9789 | I23: =IFERROR('Raw FS'!M21,0) -> 10944 | J23: =IFERROR('Raw FS'!N21,0) -> 7550
B24: ='Raw FS'!B22 -> Plant Machinery | F24: =IFERROR('Raw FS'!J22,0) -> 15307 | G24: =IFERROR('Raw FS'!K22,0) -> 16912 | H24: =IFERROR('Raw FS'!L22,0) -> 18480 | I24: =IFERROR('Raw FS'!M22,0) -> 20718 | J24: =IFERROR('Raw FS'!N22,0) -> 19423
B25: ='Raw FS'!B23 -> Equipments | F25: =IFERROR('Raw FS'!J23,0) -> 41 | G25: =IFERROR('Raw FS'!K23,0) -> 44 | H25: =IFERROR('Raw FS'!L23,0) -> 44 | I25: =IFERROR('Raw FS'!M23,0) -> 53 | J25: =IFERROR('Raw FS'!N23,0) -> 63
B26: ='Raw FS'!B24 -> Furniture n fittings | F26: =IFERROR('Raw FS'!J24,0) -> 833 | G26: =IFERROR('Raw FS'!K24,0) -> 907 | H26: =IFERROR('Raw FS'!L24,0) -> 1000 | I26: =IFERROR('Raw FS'!M24,0) -> 1068 | J26: =IFERROR('Raw FS'!N24,0) -> 282
B27: ='Raw FS'!B25 -> Railway sidings | F27: =IFERROR('Raw FS'!J25,0) -> 2 | G27: =IFERROR('Raw FS'!K25,0) -> 2 | H27: =IFERROR('Raw FS'!L25,0) -> 2 | I27: =IFERROR('Raw FS'!M25,0) -> 2 | J27: =IFERROR('Raw FS'!N25,0) -> 2
B28: ='Raw FS'!B26 -> Vehicles | F28: =IFERROR('Raw FS'!J26,0) -> 180 | G28: =IFERROR('Raw FS'!K26,0) -> 179 | H28: =IFERROR('Raw FS'!L26,0) -> 189 | I28: =IFERROR('Raw FS'!M26,0) -> 192 | J28: =IFERROR('Raw FS'!N26,0) -> 141
B29: ='Raw FS'!B27 -> Intangible Assets | F29: =IFERROR('Raw FS'!J27,0) -> 2734 | G29: =IFERROR('Raw FS'!K27,0) -> 2744 | H29: =IFERROR('Raw FS'!L27,0) -> 3490 | I29: =IFERROR('Raw FS'!M27,0) -> 3505 | J29: =IFERROR('Raw FS'!N27,0) -> 3622
B30: ='Raw FS'!B28 -> Other fixed assets | F30: =IFERROR('Raw FS'!J28,0) -> 716 | G30: =IFERROR('Raw FS'!K28,0) -> 719 | H30: =IFERROR('Raw FS'!L28,0) -> 786 | I30: =IFERROR('Raw FS'!M28,0) -> 841 | J30: =IFERROR('Raw FS'!N28,0) -> 967
B32: Gross Block | F32: =SUM(F22:F30) -> 31089 | G32: =SUM(G22:G30) -> 33436 | H32: =SUM(H22:H30) -> 36610 | I32: =SUM(I22:I30) -> 40188 | J32: =SUM(J22:J30) -> 33638
B33: Accumulated Depreciation | F33: =IFERROR(-'Raw FS'!J30,0) -> -7790 | G33: =IFERROR(-'Raw FS'!K30,0) -> -9204 | H33: =IFERROR(-'Raw FS'!L30,0) -> -10757 | I33: =IFERROR(-'Raw FS'!M30,0) -> -12368 | J33: =IFERROR(-'Raw FS'!N30,0) -> -11683
A34: # | B34: Net Non Current Assets | F34: =SUM(F32:F33) -> 23299 | G34: =SUM(G32:G33) -> 24232 | H34: =SUM(H32:H33) -> 25853 | I34: =SUM(I32:I33) -> 27820 | J34: =SUM(J32:J33) -> 21955
B36: Invested Capital | F36: =F34+F19 -> 27159 | G36: =G34+G19 -> 30106 | H36: =H34+H19 -> 32246 | I36: =I34+I19 -> 33698 | J36: =J34+J19 -> 30577
B37: NOPAT | F37: =IFERROR('Historical FS'!H25*(1-'Historical FS'!H35),0) -> 10846.709 | G37: =IFERROR('Historical FS'!I25*(1-'Historical FS'!I35),0) -> 13636.715 | H37: =IFERROR('Historical FS'!J25*(1-'Historical FS'!J35),0) -> 17435.827 | I37: =IFERROR('Historical FS'!K25*(1-'Historical FS'!K35),0) -> 17449.743 | J37: =IFERROR('Historical FS'!L25*(1-'Historical FS'!L35),0) -> 17289.802
A39: # | B39: ROIC | F39: =F37/F36 -> 0.39937808 | G39: =G37/G36 -> 0.45295672 | H39: =H37/H36 -> 0.54071286 | I39: =I37/I36 -> 0.51782726 | J39: =J37/J36 -> 0.56545124
A42: # | B42: Calculation of Reinvestment Rate | F42: ='Data Sheet'!G16 -> 44286 | G42: ='Data Sheet'!H16 -> 44651 | H42: ='Data Sheet'!I16 -> 45016 | I42: ='Data Sheet'!J16 -> 45382 | J42: ='Data Sheet'!K16 -> 45747
B44: Net CAPEX | F44: =IFERROR(SUM('Raw FS'!J57:J58),0) -> -1834 | G44: =IFERROR(SUM('Raw FS'!K57:K58),0) -> -2009 | H44: =IFERROR(SUM('Raw FS'!L57:L58),0) -> -2694 | I44: =IFERROR(SUM('Raw FS'!M57:M58),0) -> -3456 | J44: =IFERROR(SUM('Raw FS'!N57:N58),0) -> -2104
B45: Change in Working Capital | G45: =G19-F19 -> 2014 | H45: =H19-G19 -> 519 | I45: =I19-H19 -> -515 | J45: =J19-I19 -> 2744
B47: EBIT | F47: =F37 -> 10846.709 | G47: =G37 -> 13636.715 | H47: =H37 -> 17435.827 | I47: =I37 -> 17449.743 | J47: =J37 -> 17289.802
B48: Marginal Tax Rate | F48: ='Historical FS'!H35 -> 0.29654481 | G48: ='Historical FS'!I35 -> 0.278127 | H48: ='Historical FS'!J35 -> 0.27032247 | I48: ='Historical FS'!K35 -> 0.26277456 | J48: ='Historical FS'!L35 -> 0.28534247
B49: EBIT(1-T) | F49: =F47*(1-F48) -> 7630.174 | G49: =G47*(1-G48) -> 9843.9765 | H49: =H47*(1-H48) -> 12722.531 | I49: =I47*(1-I48) -> 12864.394 | J49: =J47*(1-J48) -> 12356.287
B51: Reinvestment | G51: =SUM(G44:G45) -> 5 | H51: =SUM(H44:H45) -> -2175 | I51: =SUM(I44:I45) -> -3971 | J51: =SUM(J44:J45) -> 640
B53: Reinvestment Rate | G53: =G51/G49 -> 0.00050792482 | H53: =H51/H49 -> -0.17095655 | I53: =I51/I49 -> -0.30868146 | J53: =J51/J49 -> 0.051795493
H55: 4 Year Average | J55: =AVERAGE(G53:J53) -> -0.10683365
...

Sheet DCF
B2: Calculation of PV of FCFF | F2: ='Data Sheet'!K16 -> 45747 | G2: =F2+365 -> 46112 | H2: =G2+365 -> 46477 | I2: =H2+366 -> 46843 | J2: =I2+365 -> 47208 | K2: =J2+365 -> 47573
B4: EBIT | F4: =IFERROR('Historical FS'!L25,0) -> 24193.13 | G4: =F4*(1+$E$14) -> 25730.179 | H4: =G4*(1+$E$14) -> 27364.88 | I4: =H4*(1+$E$14) -> 29103.438 | J4: =I4*(1+$E$14) -> 30952.451 | K4: =J4*(1+$E$14) -> 32918.936
B5: Tax Rate | F5: ='Peer Comps'!J12 -> 0.278127 | G5: =F5 -> 0.278127 | H5: =G5 -> 0.278127 | I5: =H5 -> 0.278127 | J5: =I5 -> 0.278127 | K5: =J5 -> 0.278127
B6: EBIT(1-T) | F6: =F4*(1-F5) -> 17464.367 | G6: =G4*(1-G5) -> 18573.921 | H6: =H4*(1-H5) -> 19753.968 | I6: =I4*(1-I5) -> 21008.986 | J6: =J4*(1-J5) -> 22343.739 | K6: =K4*(1-K5) -> 23763.291
B7: Less:Reinvestment Rate | F7: ='Intrinsic Growth'!J53 -> 0.051795493 | G7: =F7+(($L$7-$F$7)/5) -> 0.065436394 | H7: =G7+(($L$7-$F$7)/5) -> 0.079077296 | I7: =H7+(($L$7-$F$7)/5) -> 0.092718197 | J7: =I7+(($L$7-$F$7)/5) -> 0.1063591 | K7: =J7+(($L$7-$F$7)/5) -> 0.12 | L7: 0.12
B8: Free Cash Flow to Firm (FCFF) | F8: =F6*(1-F7) -> 16559.792 | G8: =G6*(1-G7) -> 17358.511 | H8: =H6*(1-H7) -> 18191.878 | I8: =I6*(1-I7) -> 19061.071 | J8: =J6*(1-J7) -> 19967.279 | K8: =K6*(1-K7) -> 20911.696
B9: Mid year convention | G9: 0.5 | H9: =G9+1 -> 1.5 | I9: =H9+1 -> 2.5 | J9: =I9+1 -> 3.5 | K9: =J9+1 -> 4.5
B10: Discounting Factor | G10: =1/(1+$E$16)^G9 -> 0.94301588 | H10: =1/(1+$E$16)^H9 -> 0.83860418 | I10: =1/(1+$E$16)^I9 -> 0.74575305 | J10: =1/(1+$E$16)^J9 -> 0.6631825 | K10: =1/(1+$E$16)^K9 -> 0.58975424
B12: PV of FCFF | G12: =G8*G10 -> 16369.352 | H12: =H8*H10 -> 15255.785 | I12: =I8*I10 -> 14214.852 | J12: =J8*J10 -> 13241.95 | K12: =K8*K10 -> 12332.762
B14: Expected Growth | E14: =Growth_assumptions!G20 -> 0.063532454
B15: Terminal Growth | E15: =Growth_assumptions!G30 -> 0.037373738
B16: WACC | E16: =WACC!J44 -> 0.12450654
B18: Calculation of Terminal Value | G18: Senstivity Analysis
G19: =E37 -> 177.16029 | H19: 0.11 | I19: 0.1245 | J19: 0.13 | K19: 0.14
B20: FCFF( | E20: =K8*(1+E15) -> 21693.245 | G20: 0.02 | H20: 180.02155 | I20: 156.05134 | J20: 148.61439 | K20: 136.84172
B21: WACC | E21: =E16 -> 0.12450654 | G21: 0.0374 | H21: 210.86738 | I21: 177.21123 | J21: 167.20217 | K21: 151.75284
B22: Terminal Growth Rate | E22: =E15 -> 0.037373738 | G22: 0.05 | H22: 244.37232 | I22: 198.70411 | J22: 185.70984 | K22: 166.14979
G23: 0.06 | H23: 282.98278 | I23: 221.73881 | J23: 205.14079 | K23: 180.80382
B24: Terminal Value | E24: =E20/(E21-E22) -> 248967.61 | G24: 0.07 | H24: 340.89847 | I24: 253.22661 | J24: 231.04873 | K24: 199.64472
B26: Calculation of Equity Value Per Share
B28: PV of FCFF | E28: =SUM(G12:K12) -> 71414.7
B29: PV of Terminal Value | E29: =E24*K10 -> 146829.71
B30: Value of Operating Asset | E30: =SUM(E28:E29) -> 218244.41
B32: Add:Cash | E32: ='Raw FS'!N39 -> 4012
B33: Less:Debt | E33: =SUM('Raw FS'!N9,'Raw FS'!N10) -> 284
B34: Value of Equity | E34: =E30+E32-E33 -> 221972.41
B35: No of Shares | E35: ='Data Sheet'!B6 -> 1252.9468
B37: Equity Value Per Share | E37: =E34/E35 -> 177.16029
B39: Share Price | E39: ='Data Sheet'!B8 -> 308.4
B40: Discount/Premium | E40: =E39/E37 -> 1.7407965

Sheet Football Field Analysis
L2: Football Field Analysis - Data Table
M3: Open Low | N3: Low | O3: Open High | P3: High
L4: Comps | M4: ='Relative Valuation'!$N$33 -> 444.12647 | N4: ='Relative Valuation'!$N$33 -> 444.12647 | O4: ='Relative Valuation'!$P$33 -> 769.46141 | P4: ='Relative Valuation'!$P$33 -> 769.46141
L5: DCF Bear | M5: =DCF!$K$20 -> 136.84172 | N5: =DCF!$K$20 -> 136.84172 | O5: =DCF!$K$24 -> 199.64472 | P5: =DCF!$K$24 -> 199.64472
L6: DCF Base | M6: =DCF!$I$20 -> 156.05134 | N6: =DCF!$I$20 -> 156.05134 | O6: =DCF!$I$24 -> 253.22661 | P6: =DCF!$I$24 -> 253.22661
L7: DCF Bull | M7: =DCF!$H$20 -> 180.02155 | N7: =DCF!$H$20 -> 180.02155 | O7: =DCF!$H$24 -> 340.89847 | P7: =DCF!$H$24 -> 340.89847
L8: 52W H/L | M8: 287 | N8: 287 | O8: 444.2 | P8: 444.2

Sheet Relative Valuation
B2: Amount in Crores
B3: Comparable Companies Valuation
D5: Market Data | J5: Financials | N5: Valuation
B6: Company | C6: Ticker | D6: Share Price | E6: Shares Outstanding | F6: Equity Value | G6: Net Debt | H6: Enterprise Value | J6: Revenue | K6: EBITDA | L6: Net Income | N6: EV/ Revenue | O6: EV/ EBITDA | P6: P/E
B8: ='RV Data'!C3 -> ITC | C8: ='RV Data'!D3 -> ITC | D8: =IFERROR('RV Data'!E3,0) -> 305 | E8: =IFERROR('RV Data'!F3,0) -> 1252.95 | F8: =E8*D8 -> 382149.75 | G8: =IFERROR('RV Data'!H3,0) -> -3649.39 | H8: =F8+G8 -> 378500.36 | J8: =IFERROR('RV Data'!L3,0) -> 75323.34 | K8: =IFERROR('RV Data'!M3,0) -> 28612.68 | L8: =IFERROR('RV Data'!N3,0) -> 17257.6 | N8: =$H8/J8 -> 5.0250077 | O8: =$H8/K8 -> 13.228413 | P8: =F8/L8 -> 22.143853
B9: ='RV Data'!C4 -> Hind. Unilever | C9: ='RV Data'!D4 -> HINDUNILVR | D9: =IFERROR('RV Data'!E4,0) -> 2231.5 | E9: =IFERROR('RV Data'!F4,0) -> 234.96 | F9: =E9*D9 -> 524313.24 | G9: =IFERROR('RV Data'!H4,0) -> -5779 | H9: =F9+G9 -> 518534.24 | J9: =IFERROR('RV Data'!L4,0) -> 64544 | K9: =IFERROR('RV Data'!M4,0) -> 16265 | L9: =IFERROR('RV Data'!N4,0) -> 14540 | N9: =$H9/J9 -> 8.0338101 | O9: =$H9/K9 -> 31.880371 | P9: =F9/L9 -> 36.060058
B10: ='RV Data'!C5 -> Nestle India | C10: ='RV Data'!D5 -> NESTLEIND | D10: =IFERROR('RV Data'!E5,0) -> 1286.4 | E10: =IFERROR('RV Data'!F5,0) -> 192.83 | F10: =E10*D10 -> 248056.51 | G10: =IFERROR('RV Data'!H5,0) -> 381.2 | H10: =F10+G10 -> 248437.71 | J10: =IFERROR('RV Data'!L5,0) -> 21910.69 | K10: =IFERROR('RV Data'!M5,0) -> 6005.29 | L10: =IFERROR('RV Data'!N5,0) -> 3315.9 | N10: =$H10/J10 -> 11.338653 | O10: =$H10/K10 -> 41.369811 | P10: =F10/L10 -> 74.8082
B11: ='RV Data'!C6 -> Varun Beverages | C11: ='RV Data'!D6 -> VBL | D11: =IFERROR('RV Data'!E6,0) -> 466.55 | E11: =IFERROR('RV Data'!F6,0) -> 338.21 | F11: =E11*D11 -> 157791.88 | G11: =IFERROR('RV Data'!H6,0) -> 509.69 | H11: =F11+G11 -> 158301.57 | J11: =IFERROR('RV Data'!L6,0) -> 21685.37 | K11: =IFERROR('RV Data'!M6,0) -> 6605.66 | L11: =IFERROR('RV Data'!N6,0) -> 3062.04 | N11: =$H11/J11 -> 7.2999246 | O11: =$H11/K11 -> 23.964534 | P11: =F11/L11 -> 51.531618
B12: ='RV Data'!C7 -> Britannia Inds. | C12: ='RV Data'!D7 -> BRITANNIA | D12: =IFERROR('RV Data'!E7,0) -> 5700 | E12: =IFERROR('RV Data'!F7,0) -> 24.09 | F12: =E12*D12 -> 137313 | G12: =IFERROR('RV Data'!H7,0) -> 1883.82 | H12: =F12+G12 -> 139196.82 | J12: =IFERROR('RV Data'!L7,0) -> 18864.86 | K12: =IFERROR('RV Data'!M7,0) -> 3813.85 | L12: =IFERROR('RV Data'!N7,0) -> 2416.46 | N12: =$H12/J12 -> 7.3786299 | O12: =$H12/K12 -> 36.497718 | P12: =F12/L12 -> 56.824032
B13: ='RV Data'!C8 -> Godrej Consumer | C13: ='RV Data'!D8 -> GODREJCP | D13: =IFERROR('RV Data'!E8,0) -> 1104.8 | E13: =IFERROR('RV Data'!F8,0) -> 102.32 | F13: =E13*D13 -> 113043.14 | G13: =IFERROR('RV Data'!H8,0) -> 3630.43 | H13: =F13+G13 -> 116673.57 | J13: =IFERROR('RV Data'!L8,0) -> 15184.02 | K13: =IFERROR('RV Data'!M8,0) -> 3331.5 | L13: =IFERROR('RV Data'!N8,0) -> 1821.6 | N13: =$H13/J13 -> 7.6839708 | O13: =$H13/K13 -> 35.021332 | P13: =F13/L13 -> 62.057058
B14: ='RV Data'!C9 -> Tata Consumer | C14: ='RV Data'!D9 -> TATACONSUM | D14: =IFERROR('RV Data'!E9,0) -> 1120.4 | E14: =IFERROR('RV Data'!F9,0) -> 98.96 | F14: =E14*D14 -> 110874.78 | G14: =IFERROR('RV Data'!H9,0) -> -241.75 | H14: =F14+G14 -> 110633.03 | J14: =IFERROR('RV Data'!L9,0) -> 19465.03 | K14: =IFERROR('RV Data'!M9,0) -> 3234.93 | L14: =IFERROR('RV Data'!N9,0) -> 1471.5 | N14: =$H14/J14 -> 5.6836817 | O14: =$H14/K14 -> 34.199514 | P14: =F14/L14 -> 75.348137
B15: ='RV Data'!C10 -> Marico | C15: ='RV Data'!D10 -> MARICO | D15: =IFERROR('RV Data'!E10,0) -> 760.7 | E15: =IFERROR('RV Data'!F10,0) -> 129.81 | F15: =E15*D15 -> 98746.467 | G15: =IFERROR('RV Data'!H10,0) -> -202 | H15: =F15+G15 -> 98544.467 | J15: =IFERROR('RV Data'!L10,0) -> 13008 | K15: =IFERROR('RV Data'!M10,0) -> 2459 | L15: =IFERROR('RV Data'!N10,0) -> 1750 | N15: =$H15/J15 -> 7.5756817 | O15: =$H15/K15 -> 40.075017 | P15: =F15/L15 -> 56.426553
B16: ='RV Data'!C11 -> United Spirits | C16: ='RV Data'!D11 -> MCDOWELL-N | D16: =IFERROR('RV Data'!E11,0) -> 1307.7 | E16: =IFERROR('RV Data'!F11,0) -> 72.74 | F16: =E16*D16 -> 95122.098 | G16: =IFERROR('RV Data'!H11,0) -> -1618 | H16: =F16+G16 -> 93504.098 | J16: =IFERROR('RV Data'!L11,0) -> 12919 | K16: =IFERROR('RV Data'!M11,0) -> 2646 | L16: =IFERROR('RV Data'!N11,0) -> 1720 | N16: =$H16/J16 -> 7.2377195 | O16: =$H16/K16 -> 35.337906 | P16: =F16/L16 -> 55.303545
